Workbook
Name _xlchart.v1.9: '排出量'!$P$64:$P$135
Name _xlchart.v1.23: #REF!
Name _xlchart.v1.17: #REF!
Name _xlchart.v1.21: #REF!
Name _xlchart.v1.15: #REF!
Name _xlchart.v1.8: '排出量'!$P$63
Name _xlchart.v1.16: #REF!
Name _xlchart.v1.1: '排出量'!$E$130:$E$155
Name _xlchart.v1.0: '排出量'!$E$129
Name _xlchart.v1.6: '排出量'!$O$63
Name _xlchart.v1.22: #REF!
Name _xlchart.v1.18: #REF!
Name _xlchart.v1.12: #REF!
Name _xlchart.v1.10: '排出量'!$Q$63
Name _xlchart.v1.4: '排出量'!$G$129
Name _xlchart.v1.14: #REF!
Name _xlchart.v1.11: '排出量'!$Q$64:$Q$135
Name _xlchart.v1.5: '排出量'!$G$130:$G$155
Name _xlchart.v1.7: '排出量'!$O$64:$O$135
Name _xlchart.v1.19: #REF!
Name _xlchart.v1.3: '排出量'!$F$130:$F$155
Name _xlchart.v1.20: #REF!
Name _xlchart.v1.2: '排出量'!$F$129
Name _xlchart.v1.13: #REF!

Sheet 使用量
A1: ■電気・ガス・水道使用量
A2: No | B2: 月 | C2: 月 | D2: 月 | E2: 電気[kWh] | F2: 電気代 | G2: ガス[㎥] | H2: ガス代 | I2: 水道[㎥] | J2: 水道代
A3: 1 | B3: 2017 | C3: 5 | D3: 2017年5月 | E3: 153 | G3: 16 | I3: 8
A4: 2 | B4: 2017 | C4: 6 | D4: 2017年6月 | I4: 6.5
A5: 3 | B5: 2017 | C5: 7 | D5: 2017年7月 | E5: 159 | I5: 6.5
A6: 4 | B6: 2017 | C6: 8 | D6: 2017年8月 | E6: 175 | G6: 7 | I6: 7.5
A7: 5 | B7: 2017 | C7: 9 | D7: 2017年9月 | E7: 158 | G7: 8 | I7: 7.5
A8: 6 | B8: 2017 | C8: 10 | D8: 2017年10月 | E8: 140 | G8: 16
A9: 7 | B9: 2017 | C9: 11 | D9: 2017年11月 | E9: 158 | G9: 24
A10: 8 | B10: 2017 | C10: 12 | D10: 2017年12月 | I10: 8.5
A11: No | B11: 月 | C11: 月 | D11: 月 | E11: 電気[kWh] | F11: 電気代[円] | G11: ガス[㎥] | H11: ガス代 | I11: 水道[㎥] | J11: 水道代
A12: 9 | B12: 2018 | C12: 1 | D12: 2018/1 | E12: 194 | F12: 4738 | G12: 25 | H12: 4319 | I12: 8.5 | J12: 1675.5
A13: 10 | B13: 2018 | C13: 2 | D13: 2018/2 | E13: 185 | F13: 4521 | G13: 24 | H13: 4200 | I13: 9.5 | J13: 3637
A14: 11 | B14: 2018 | C14: 3 | D14: 2018/3 | E14: 153 | F14: 3732 | G14: 21 | H14: 3853 | I14: 9.5
A15: 12 | B15: 2018 | C15: 4 | D15: 2018/4 | E15: 136 | F15: 3332 | G15: 21 | H15: 3885 | I15: 8 | J15: 3209
A16: 13 | B16: 2018 | C16: 5 | D16: 2018/5 | E16: 148 | F16: 3720 | G16: 10 | H16: 2418 | I16: 8
A17: 14 | B17: 2018 | C17: 6 | D17: 2018/6 | E17: 135 | F17: 3396 | G17: 11 | H17: 2567 | I17: 8 | J17: 3209
A18: 15 | B18: 2018 | C18: 7 | D18: 2018/7 | E18: 192 | F18: 4928 | G18: 9 | H18: 2294 | I18: 8
A19: 16 | B19: 2018 | C19: 8 | D19: 2018/8 | E19: 218 | F19: 5656 | G19: 5 | H19: 1743 | I19: 7 | J19: 3161
A20: 17 | B20: 2018 | C20: 9 | D20: 2018/9 | E20: 193 | F20: 5030 | G20: 8 | H20: 2170 | I20: 7
A21: 18 | B21: 2018 | C21: 10 | D21: 2018/10 | E21: 141 | F21: 3662 | G21: 12 | H21: 2748 | I21: 9 | J21: 3494
A22: 19 | B22: 2018 | C22: 11 | D22: 2018/11 | E22: 150 | F22: 3948 | G22: 14 | H22: 3050 | I22: 9
A23: 20 | B23: 2018 | C23: 12 | D23: 2018/12 | E23: 161 | F23: 4281 | G23: 21 | H23: 4068 | I23: 11 | J23: 4293
A24: 21 | B24: 2019 | C24: 1 | D24: 2019/1 | E24: 197 | F24: 5346 | G24: 33 | H24: 5698 | I24: 11
A25: 22 | B25: 2019 | C25: 2 | D25: 2019/2 | E25: 169 | F25: 4607 | G25: 22 | H25: 4283 | I25: 10 | J25: 3779
A26: 23 | B26: 2019 | C26: 3 | D26: 2019/3 | E26: 143 | F26: 3303 | G26: 22 | H26: 4304 | I26: 10
A27: 24 | B27: 2019 | C27: 4 | D27: 2019/4 | E27: 137 | F27: 3152 | G27: 28 | H27: 4799 | I27: 10.5 | J27: 4036
A28: 25 | B28: 2019 | C28: 5 | D28: 2019/5 | E28: 136 | F28: 3578 | G28: 19 | H28: 3561 | I28: 10.5
A29: 26 | B29: 2019 | C29: 6 | D29: 2019/6 | E29: 172 | F29: 4504 | G29: 11 | H29: 2362 | I29: 8.5 | J29: 3351
A30: 27 | B30: 2019 | C30: 7 | D30: 2019/7 | E30: 178 | F30: 4642 | G30: 12 | H30: 2487 | I30: 8.5
A31: 28 | B31: 2019 | C31: 8 | D31: 2019/8 | E31: 249 | F31: 6476 | G31: 11 | H31: 2316 | I31: 9 | J31: 3494
A32: 29 | B32: 2019 | C32: 9 | D32: 2019/9 | E32: 211 | F32: 5417 | G32: 12 | H32: 2428 | I32: 9
A33: 30 | B33: 2019 | C33: 10 | D33: 2019/10 | E33: 182 | F33: 4631 | G33: 11 | H33: 2279 | I33: 9 | J33: 3525
A34: 31 | B34: 2019 | C34: 11 | D34: 2019/11 | E34: 150 | F34: 3857 | G34: 16 | H34: 3036 | I34: 9
A35: 32 | B35: 2019 | C35: 12 | D35: 2019/12 | E35: 165 | F35: 4232 | G35: 21 | H35: 3730 | I35: 9 | J35: 3559
A36: 33 | B36: 2020 | C36: 1 | D36: 2020/1 | E36: 199 | F36: 5111 | G36: 27 | H36: 4484 | I36: 9
A37: 34 | B37: 2020 | C37: 2 | D37: 2020/2 | E37: 170 | F37: 4332 | G37: 19 | H37: 3440 | I37: 9 | J37: 3559
A38: 35 | B38: 2020 | C38: 3 | D38: 2020/3 | E38: 105 | F38: 2729 | G38: 19 | H38: 3446 | I38: 9
A39: 36 | B39: 2020 | C39: 4 | D39: 2020/4 | E39: 107 | F39: 2775 | G39: 18 | H39: 3308 | I39: 7 | J39: 3220
A40: 37 | B40: 2020 | C40: 5 | D40: 2020/5 | E40: 95 | F40: 2535 | G40: 13 | H40: 2600 | I40: 7
...

Sheet 排出量
A1: ■二酸化炭素排出量[単位:kg]
A2: No | B2: 月 | C2: 月 | D2: 月 | E2: CO2排出量計[kg] | F2: 光熱費(円) | G2: 電気代 | H2: ガス代 | I2: 水道代 | L2: 2018 | M2: 2019 | N2: 2020
A3: 1 | B3: 2017 | C3: 5 | D3: 2017/5 | E3: 116.896 | L3: 1475.406 | M3: 1577.134 | N3: 1177.744
A4: 2 | B4: 2017 | C4: 6 | D4: 2017/6 | N4: =1-N3/M3 -> 0.25323784
A5: 3 | B5: 2017 | C5: 7 | D5: 2017/7
A6: 4 | B6: 2017 | C6: 8 | D6: 2017/8 | E6: 107.91
A7: 5 | B7: 2017 | C7: 9 | D7: 2017/9 | E7: 101.436
A8: 6 | B8: 2017 | C8: 10 | D8: 2017/10
A9: 7 | B9: 2017 | C9: 11 | D9: 2017/11
A10: 8 | B10: 2017 | C10: 12 | D10: 2017/12
A11: 9 | B11: 2018 | C11: 1 | D11: 2018/1 | E11: ='使用量'!E12*Sheet2!$B$3+'使用量'!G12*Sheet2!$C$3+'使用量'!I12*Sheet2!$D$3 -> 161.849 | F11: =SUM(G11:I11) -> 10732.5 | G11: ='使用量'!F12 -> 4738 | H11: ='使用量'!H12 -> 4319 | I11: ='使用量'!J12 -> 1675.5
A12: 10 | B12: 2018 | C12: 2 | D12: 2018/2 | E12: ='使用量'!E13*Sheet2!$B$3+'使用量'!G13*Sheet2!$C$3+'使用量'!I13*Sheet2!$D$3 -> 155.6 | F12: =SUM(G12:I12) -> 10539.5 | G12: ='使用量'!F13 -> 4521 | H12: ='使用量'!H13 -> 4200 | I12: 1818.5
A13: 11 | B13: 2018 | C13: 3 | D13: 2018/3 | E13: ='使用量'!E14*Sheet2!$B$3+'使用量'!G14*Sheet2!$C$3+'使用量'!I14*Sheet2!$D$3 -> 132.298 | F13: =SUM(G13:I13) -> 9403.5 | G13: ='使用量'!F14 -> 3732 | H13: ='使用量'!H14 -> 3853 | I13: 1818.5
A14: 12 | B14: 2018 | C14: 4 | D14: 2018/4 | E14: ='使用量'!E15*Sheet2!$B$3+'使用量'!G15*Sheet2!$C$3+'使用量'!I15*Sheet2!$D$3 -> 122.466 | F14: =SUM(G14:I14) -> 8821.5 | G14: ='使用量'!F15 -> 3332 | H14: ='使用量'!H15 -> 3885 | I14: 1604.5
A15: 13 | B15: 2018 | C15: 5 | D15: 2018/5 | E15: ='使用量'!E16*Sheet2!$B$3+'使用量'!G16*Sheet2!$C$3+'使用量'!I16*Sheet2!$D$3 -> 104.408 | F15: =SUM(G15:I15) -> 7742.5 | G15: ='使用量'!F16 -> 3720 | H15: ='使用量'!H16 -> 2418 | I15: 1604.5
A16: 14 | B16: 2018 | C16: 6 | D16: 2018/6 | E16: ='使用量'!E17*Sheet2!$B$3+'使用量'!G17*Sheet2!$C$3+'使用量'!I17*Sheet2!$D$3 -> 99.845 | F16: =SUM(G16:I16) -> 7567.5 | G16: ='使用量'!F17 -> 3396 | H16: ='使用量'!H17 -> 2567 | I16: 1604.5
A17: 15 | B17: 2018 | C17: 7 | D17: 2018/7 | E17: ='使用量'!E18*Sheet2!$B$3+'使用量'!G18*Sheet2!$C$3+'使用量'!I18*Sheet2!$D$3 -> 125.122 | F17: =SUM(G17:I17) -> 8826.5 | G17: ='使用量'!F18 -> 4928 | H17: ='使用量'!H18 -> 2294 | I17: 1604.5
A18: 16 | B18: 2018 | C18: 8 | D18: 2018/8 | E18: ='使用量'!E19*Sheet2!$B$3+'使用量'!G19*Sheet2!$C$3+'使用量'!I19*Sheet2!$D$3 -> 129.178 | F18: =SUM(G18:I18) -> 8979.5 | G18: ='使用量'!F19 -> 5656 | H18: ='使用量'!H19 -> 1743 | I18: 1580.5
A19: 17 | B19: 2018 | C19: 9 | D19: 2018/9 | E19: ='使用量'!E20*Sheet2!$B$3+'使用量'!G20*Sheet2!$C$3+'使用量'!I20*Sheet2!$D$3 -> 122.783 | F19: =SUM(G19:I19) -> 8780.5 | G19: ='使用量'!F20 -> 5030 | H19: ='使用量'!H20 -> 2170 | I19: 1580.5
A20: 18 | B20: 2018 | C20: 10 | D20: 2018/10 | E20: ='使用量'!E21*Sheet2!$B$3+'使用量'!G21*Sheet2!$C$3+'使用量'!I21*Sheet2!$D$3 -> 105.831 | F20: =SUM(G20:I20) -> 8157 | G20: ='使用量'!F21 -> 3662 | H20: ='使用量'!H21 -> 2748 | I20: 1747
A21: 19 | B21: 2018 | C21: 11 | D21: 2018/11 | E21: ='使用量'!E22*Sheet2!$B$3+'使用量'!G22*Sheet2!$C$3+'使用量'!I22*Sheet2!$D$3 -> 114.94 | F21: =SUM(G21:I21) -> 8745 | G21: ='使用量'!F22 -> 3948 | H21: ='使用量'!H22 -> 3050 | I21: 1747
A22: 20 | B22: 2018 | C22: 12 | D22: 2018/12 | E22: ='使用量'!E23*Sheet2!$B$3+'使用量'!G23*Sheet2!$C$3+'使用量'!I23*Sheet2!$D$3 -> 137.441 | F22: =SUM(G22:I22) -> 10495.5 | G22: ='使用量'!F23 -> 4281 | H22: ='使用量'!H23 -> 4068 | I22: 2146.5 | J22: 2019年
A23: 21 | B23: 2019 | C23: 1 | D23: 2019/1 | E23: ='使用量'!E24*Sheet2!$B$3+'使用量'!G24*Sheet2!$C$3+'使用量'!I24*Sheet2!$D$3 -> 182.717 | F23: =SUM(G23:I23) -> 13190.5 | G23: ='使用量'!F24 -> 5346 | H23: ='使用量'!H24 -> 5698 | I23: 2146.5 | J23: =average(E11:E36) -> 133.13919 | K23: =average(F11:F36) -> 9494.4615
A24: 22 | B24: 2019 | C24: 2 | D24: 2019/2 | E24: ='使用量'!E25*Sheet2!$B$3+'使用量'!G25*Sheet2!$C$3+'使用量'!I25*Sheet2!$D$3 -> 143.169 | F24: =SUM(G24:I24) -> 10779.5 | G24: ='使用量'!F25 -> 4607 | H24: ='使用量'!H25 -> 4283 | I24: 1889.5
A25: 23 | B25: 2019 | C25: 3 | D25: 2019/3 | E25: ='使用量'!E26*Sheet2!$B$3+'使用量'!G26*Sheet2!$C$3+'使用量'!I26*Sheet2!$D$3 -> 129.623 | F25: =SUM(G25:I25) -> 9496.5 | G25: ='使用量'!F26 -> 3303 | H25: ='使用量'!H26 -> 4304 | I25: 1889.5
A26: 24 | B26: 2019 | C26: 4 | D26: 2019/4 | E26: ='使用量'!E27*Sheet2!$B$3+'使用量'!G27*Sheet2!$C$3+'使用量'!I27*Sheet2!$D$3 -> 140.082 | F26: =SUM(G26:I26) -> 9969 | G26: ='使用量'!F27 -> 3152 | H26: ='使用量'!H27 -> 4799 | I26: 2018
A27: 25 | B27: 2019 | C27: 5 | D27: 2019/5 | E27: ='使用量'!E28*Sheet2!$B$3+'使用量'!G28*Sheet2!$C$3+'使用量'!I28*Sheet2!$D$3 -> 119.671 | F27: =SUM(G27:I27) -> 9157 | G27: ='使用量'!F28 -> 3578 | H27: ='使用量'!H28 -> 3561 | I27: 2018
A28: 26 | B28: 2019 | C28: 6 | D28: 2019/6 | E28: ='使用量'!E29*Sheet2!$B$3+'使用量'!G29*Sheet2!$C$3+'使用量'!I29*Sheet2!$D$3 -> 119.447 | F28: =SUM(G28:I28) -> 8541.5 | G28: ='使用量'!F29 -> 4504 | H28: ='使用量'!H29 -> 2362 | I28: 1675.5
A29: 27 | B29: 2019 | C29: 7 | D29: 2019/7 | E29: ='使用量'!E30*Sheet2!$B$3+'使用量'!G30*Sheet2!$C$3+'使用量'!I30*Sheet2!$D$3 -> 124.783 | F29: =SUM(G29:I29) -> 8804.5 | G29: ='使用量'!F30 -> 4642 | H29: ='使用量'!H30 -> 2487 | I29: 1675.5
A30: 28 | B30: 2019 | C30: 8 | D30: 2019/8 | E30: ='使用量'!E31*Sheet2!$B$3+'使用量'!G31*Sheet2!$C$3+'使用量'!I31*Sheet2!$D$3 -> 159.889 | F30: =SUM(G30:I30) -> 10539 | G30: ='使用量'!F31 -> 6476 | H30: ='使用量'!H31 -> 2316 | I30: 1747
A31: 29 | B31: 2019 | C31: 9 | D31: 2019/9 | E31: ='使用量'!E32*Sheet2!$B$3+'使用量'!G32*Sheet2!$C$3+'使用量'!I32*Sheet2!$D$3 -> 142.301 | F31: =SUM(G31:I31) -> 9592 | G31: ='使用量'!F32 -> 5417 | H31: ='使用量'!H32 -> 2428 | I31: 1747
A32: 30 | B32: 2019 | C32: 10 | D32: 2019/10 | E32: ='使用量'!E33*Sheet2!$B$3+'使用量'!G33*Sheet2!$C$3+'使用量'!I33*Sheet2!$D$3 -> 124.982 | F32: =SUM(G32:I32) -> 8672.5 | G32: ='使用量'!F33 -> 4631 | H32: ='使用量'!H33 -> 2279 | I32: 1762.5
A33: 31 | B33: 2019 | C33: 11 | D33: 2019/11 | E33: ='使用量'!E34*Sheet2!$B$3+'使用量'!G34*Sheet2!$C$3+'使用量'!I34*Sheet2!$D$3 -> 119.36 | F33: =SUM(G33:I33) -> 8655.5 | G33: ='使用量'!F34 -> 3857 | H33: ='使用量'!H34 -> 3036 | I33: 1762.5
A34: 32 | B34: 2019 | C34: 12 | D34: 2019/12 | E34: ='使用量'!E35*Sheet2!$B$3+'使用量'!G35*Sheet2!$C$3+'使用量'!I35*Sheet2!$D$3 -> 138.225 | F34: =SUM(G34:I34) -> 9741.5 | G34: ='使用量'!F35 -> 4232 | H34: ='使用量'!H35 -> 3730 | I34: 1779.5
A35: 33 | B35: 2020 | C35: 1 | D35: 2020/1 | E35: ='使用量'!E36*Sheet2!$B$3+'使用量'!G36*Sheet2!$C$3+'使用量'!I36*Sheet2!$D$3 -> 169.199 | F35: =SUM(G35:I35) -> 11374.5 | G35: ='使用量'!F36 -> 5111 | H35: ='使用量'!H36 -> 4484 | I35: 1779.5
A36: 34 | B36: 2020 | C36: 2 | D36: 2020/2 | E36: ='使用量'!E37*Sheet2!$B$3+'使用量'!G37*Sheet2!$C$3+'使用量'!I37*Sheet2!$D$3 -> 136.41 | F36: =SUM(G36:I36) -> 9551.5 | G36: ='使用量'!F37 -> 4332 | H36: ='使用量'!H37 -> 3440 | I36: 1779.5 | J36: 2020年
A37: 35 | B37: 2020 | C37: 3 | D37: 2020/3 | E37: ='使用量'!E38*Sheet2!$B$3+'使用量'!G38*Sheet2!$C$3+'使用量'!I38*Sheet2!$D$3 -> 102.545 | F37: =SUM(G37:I37) -> 7954.5 | G37: ='使用量'!F38 -> 2729 | H37: ='使用量'!H38 -> 3446 | I37: 1779.5 | J37: =average(E37:E48) -> 101.44325 | K37: =average(F37:F48) -> 7403.0833 | L37: =SUM(E25:E36) -> 1623.972 | M37: =SUM(E37:E48) -> 1217.319 | N37: =SUM(E61:E72) -> 424.45 | O37: =L37-N37 -> 1199.522
A38: 36 | B38: 2020 | C38: 4 | D38: 2020/4 | E38: ='使用量'!E39*Sheet2!$B$3+'使用量'!G39*Sheet2!$C$3+'使用量'!I39*Sheet2!$D$3 -> 100.077 | F38: =SUM(G38:I38) -> 7693 | G38: ='使用量'!F39 -> 2775 | H38: ='使用量'!H39 -> 3308 | I38: 1610 | L38: =SUM(F25:F36) -> 114095 | M38: =SUM(F37:F48) -> 88837 | N38: =SUM(F61:F72) -> 103517 | O38: =L38-N38 -> 10578
A39: 37 | B39: 2020 | C39: 5 | D39: 2020/5 | E39: ='使用量'!E40*Sheet2!$B$3+'使用量'!G40*Sheet2!$C$3+'使用量'!I40*Sheet2!$D$3 -> 82.775 | F39: =SUM(G39:I39) -> 6745 | G39: ='使用量'!F40 -> 2535 | H39: ='使用量'!H40 -> 2600 | I39: 1610
A40: 38 | B40: 2020 | C40: 6 | D40: 2020/6 | E40: ='使用量'!E41*Sheet2!$B$3+'使用量'!G41*Sheet2!$C$3+'使用量'!I41*Sheet2!$D$3 -> 78.428 | F40: =SUM(G40:I40) -> 6349.5 | G40: ='使用量'!F41 -> 2694 | H40: ='使用量'!H41 -> 2033 | I40: 1622.5
...

Sheet 再エネ比較
A1: ■光熱費[\]
A2: No | B2: 年 | C2: 月 | D2: 月 | E2: 非再エネ コスト | F2: 再エネ コスト | G2: ガス | H2: 水道 | I2: 非再エネ CO2:コスト | J2: 再エネ CO2:コスト | K2: 増加率
A3: 1 | B3: 2017 | C3: 5 | D3: 2017/5
A4: 2 | B4: 2017 | C4: 6 | D4: 2017/6
A5: 3 | B5: 2017 | C5: 7 | D5: 2017/7
A6: 4 | B6: 2017 | C6: 8 | D6: 2017/8
A7: 5 | B7: 2017 | C7: 9 | D7: 2017/9
A8: 6 | B8: 2017 | C8: 10 | D8: 2017/10
A9: 7 | B9: 2017 | C9: 11 | D9: 2017/11
A10: 8 | B10: 2017 | C10: 12 | D10: 2017/12
A11: 9 | B11: 2018 | C11: 1 | D11: 2018/1 | E11: ='使用量'!F12 -> 4738
A12: 10 | B12: 2018 | C12: 2 | D12: 2018/2 | E12: ='使用量'!F13 -> 4521
A13: 11 | B13: 2018 | C13: 3 | D13: 2018/3 | E13: ='使用量'!F14 -> 3732
A14: 12 | B14: 2018 | C14: 4 | D14: 2018/4 | E14: ='使用量'!F15 -> 3332
A15: 13 | B15: 2018 | C15: 5 | D15: 2018/5 | E15: ='使用量'!F16 -> 3720
A16: 14 | B16: 2018 | C16: 6 | D16: 2018/6 | E16: ='使用量'!F17 -> 3396
A17: 15 | B17: 2018 | C17: 7 | D17: 2018/7 | E17: ='使用量'!F18 -> 4928
A18: 16 | B18: 2018 | C18: 8 | D18: 2018/8 | E18: ='使用量'!F19 -> 5656
A19: 17 | B19: 2018 | C19: 9 | D19: 2018/9 | E19: ='使用量'!F20 -> 5030
A20: 18 | B20: 2018 | C20: 10 | D20: 2018/10 | E20: ='使用量'!F21 -> 3662
A21: 19 | B21: 2018 | C21: 11 | D21: 2018/11 | E21: ='使用量'!F22 -> 3948
A22: 20 | B22: 2018 | C22: 12 | D22: 2018/12 | E22: ='使用量'!F23 -> 4281
... A39: 37 | B39: 2020 | C39: 5 | D39: 2020/5 | E39: ='使用量'!F40 -> 2535
A40: 38 | B40: 2020 | C40: 6 | D40: 2020/6 | E40: ='使用量'!F41 -> 2694 | F40: 3305.38 | G40: 2033 | H40: 1622.5 | I40: =SUM(E40+G40+H40) -> 6349.5 | J40: =SUM(F40:H40) -> 6960.88 | K40: =(J40-I40)/I40 -> 0.096287897
A41: 39 | B41: 2020 | C41: 7 | D41: 2020/7 | E41: ='使用量'!F42 -> 2842 | F41: 3413.52 | G41: 2030 | H41: 1622.5 | I41: =SUM(E41+G41+H41) -> 6494.5 | J41: =SUM(F41:H41) -> 7066.02 | K41: =(J41-I41)/I41 -> 0.088000616
A42: 40 | B42: 2020 | C42: 8 | D42: 2020/8 | E42: ='使用量'!F43 -> 4123 | F42: 4647.16 | G42: 2027 | H42: 1610 | I42: =SUM(E42+G42+H42) -> 7760 | J42: =SUM(F42:H42) -> 8284.16 | K42: =(J42-I42)/I42 -> 0.067546392
A43: 41 | B43: 2020 | C43: 9 | D43: 2020/9 | E43: ='使用量'!F44 -> 4752 | F43: 5207.76 | G43: 1730 | H43: 1610 | I43: =SUM(E43+G43+H43) -> 8092 | J43: =SUM(F43:H43) -> 8547.76 | K43: =(J43-I43)/I43 -> 0.056322294
A44: 42 | B44: 2020 | C44: 10 | D44: 2020/10 | E44: ='使用量'!F45 -> 2686 | F44: 3428.52 | G44: 2784 | H44: 1622.5 | I44: =SUM(E44+G44+H44) -> 7092.5 | J44: =SUM(F44:H44) -> 7835.02 | K44: =(J44-I44)/I44 -> 0.10469087
A45: 43 | B45: 2020 | C45: 11 | D45: 2020/11 | E45: ='使用量'!F46 -> 2452 | F45: 3209.2 | G45: 2186 | H45: 1622.5 | I45: =SUM(E45+G45+H45) -> 6260.5 | J45: =SUM(F45:H45) -> 7017.7 | K45: =(J45-I45)/I45 -> 0.12094881
A46: 44 | B46: 2020 | C46: 12 | D46: 2020/12 | E46: ='使用量'!F47 -> 2396 | F46: 3149.85 | G46: 3264 | H46: 1925 | I46: =SUM(E46+G46+H46) -> 7585 | J46: =SUM(F46:H46) -> 8338.85 | K46: =(J46-I46)/I46 -> 0.099386948
A47: 45 | B47: 2021 | C47: 1 | D47: 2021/1 | E47: ='使用量'!F48 -> 2570 | F47: 3382.92 | G47: 4731 | H47: 1925 | I47: =SUM(E47+G47+H47) -> 9226 | J47: =SUM(F47:H47) -> 10038.92 | K47: =(J47-I47)/I47 -> 0.088111858
A48: 46 | B48: 2021 | C48: 2 | D48: 2021/2 | E48: ='使用量'!F49 -> 2503 | F48: 3533.8 | G48: 3447 | H48: 1634.5 | I48: =SUM(E48+G48+H48) -> 7584.5 | J48: =SUM(F48:H48) -> 8615.3 | K48: =(J48-I48)/I48 -> 0.13590876
A49: 47 | B49: 2021 | C49: 3 | D49: 2021/3 | E49: ='使用量'!F50 -> 2253 | F49: 3615.4 | G49: 3722 | H49: 1634.5 | I49: =SUM(E49+G49+H49) -> 7609.5 | J49: =SUM(F49:H49) -> 8971.9 | K49: =(J49-I49)/I49 -> 0.17903936
A50: 48 | B50: 2021 | C50: 4 | D50: 2021/4 | E50: 2394 | F50: 3747.09 | G50: 2719 | H50: 1586 | I50: =SUM(E50+G50+H50) -> 6699 | J50: =SUM(F50:H50) -> 8052.09 | K50: =(J50-I50)/I50 -> 0.20198388
A51: 49 | B51: 2021 | C51: 5 | D51: 2021/5 | E51: 2440 | F51: 3649.68 | G51: 1974 | H51: 1586 | I51: =SUM(E51+G51+H51) -> 6000 | J51: =SUM(F51:H51) -> 7209.68 | K51: =(J51-I51)/I51 -> 0.20161333
A52: 50 | B52: 2021 | C52: 6 | D52: 2021/6 | E52: =25.54*'使用量'!E53-107.38 -> 2421.08 | F52: 3731 | G52: 1576 | H52: 1562 | I52: =SUM(E52+G52+H52) -> 5559.08 | J52: =SUM(F52:H52) -> 6869 | K52: =(J52-I52)/I52 -> 0.23563611 | L52: 3731 | M52: 2694 | N52: =1-L52/M52 -> -0.38492947 | O52: 1576 | P52: 2033 | Q52: =1-O52/P52 -> 0.22479095 | R52: 1562 | S52: 1622.5 | T52: =1-R52/S52 -> 0.037288136
A53: 51 | B53: 2021 | C53: 7 | D53: 2021/7 | E53: =25.54*'使用量'!E54-107.38 -> 2650.94 | F53: 4006 | G53: 1746 | H53: 1562 | I53: =SUM(E53+G53+H53) -> 5958.94 | J53: =SUM(F53:H53) -> 7314 | K53: =(J53-I53)/I53 -> 0.2273995 | L53: 4006 | M53: 2842 | N53: =1-L53/M53 -> -0.40957072 | O53: 1746 | P53: 2030 | Q53: =1-O53/P53 -> 0.13990148 | R53: 1562 | S53: 1622.5 | T53: =1-R53/S53 -> 0.037288136
A54: 52 | B54: 2021 | C54: 8 | D54: 2021/8 | E54: =25.54*'使用量'!E55-107.38 -> 4770.76 | I54: =SUM(E54+G54+H54) -> 4770.76 | J54: =SUM(F54:H54) -> 0 | K54: =(J54-I54)/I54 -> -1
A55: 53 | B55: 2021 | C55: 9 | D55: 2021/9 | E55: =25.54*'使用量'!E56-107.38 -> 3314.98 | I55: =SUM(E55+G55+H55) -> 3314.98 | J55: =SUM(F55:H55) -> 0 | K55: =(J55-I55)/I55 -> -1 | L55: 6869 | M55: 6349.5 | N55: =1-L55/M55 -> -0.081817466
A56: 54 | B56: 2021 | C56: 10 | D56: 2021/10 | E56: =25.54*'使用量'!E57-107.38 -> 2727.56 | I56: =SUM(E56+G56+H56) -> 2727.56 | J56: =SUM(F56:H56) -> 0 | K56: =(J56-I56)/I56 -> -1 | L56: 7314 | M56: 6494.5 | N56: =1-L56/M56 -> -0.12618369
...

Sheet 東京都気温
A1: 東京都 温室効果ガス排出量と年間気温
B2: 降水量[mm] | C2: 温室効果ガス[万t-COeq] | D2: 気温[℃]
A3: 1952 | B3: 1640.6 | D3: 14.6
A4: 1953 | B4: 1519.4 | D4: 14.6
A5: 1954 | B5: 1770.7 | D5: 14.8
A6: 1955 | B6: 1553.9 | D6: 15.5
A7: 1956 | B7: 1657.3 | D7: 14.7
A8: 1957 | B8: 1500 | D8: 14.9
A9: 1958 | B9: 1804.9 | D9: 15.2
A10: 1959 | B10: 1626.3 | D10: 15.7
A11: 1960 | B11: 1281.9 | D11: 15.4
A12: 1961 | B12: 1260.2 | D12: 15.9
A13: 1962 | B13: 1256 | D13: 15.4
A14: 1963 | B14: 1575 | D14: 15
... A39: 1988 | B39: 1515.5 | D39: 15.4
A40: 1989 | B40: 1937.5 | C40: 温室効果ガス[万t-COeq] | D40: 16.4
A41: 1990 | B41: 1512.5 | C41: 5764 | D41: 17
A42: 1991 | B42: 2042 | C42: 6065 | D42: 16.4
A43: 1992 | B43: 1619.5 | C43: 6190 | D43: 16
A44: 1993 | B44: 1872.5 | C44: 6001 | D44: 15.5
A45: 1994 | B45: 1131.5 | C45: 6243 | D45: 16.9
A46: 1995 | B46: 1220 | C46: 6228 | D46: 16.3
A47: 1996 | B47: 1333.5 | C47: 6109 | D47: 15.8
A48: 1997 | B48: 1302 | C48: 6174 | D48: 16.7
A49: 1998 | B49: 1546.5 | C49: 6079 | D49: 16.7
A50: 1999 | B50: 1622 | C50: 6120 | D50: 17
A51: 2000 | B51: 1603 | C51: 6220 | D51: 16.9
A52: 2001 | B52: 1491 | C52: 5985 | D52: 16.5
... A68: 2017 | B68: 1430 | C68: 6485 | D68: 15.8
A69: 2018 | B69: 1445.5 | D69: 16.8
A70: 2019 | B70: 1874 | D70: 16.5
A71: 2020 | B71: 1590 | D71: 16.5
A72: 2021 | D72: 16.6
A73: 2022 | D73: 16.4

Sheet Sheet2
A1: ■二酸化炭素排出量算出のための係数
A2: No | B2: 電気[kWh] | C2: ガス[㎥] | D2: 水道[㎥]
A3: 1 | B3: 0.521 | C3: 2.21 | D3: 0.65
B4: 0
